[2025-02-01T01:58:22.825+0000] {taskinstance.py:1103} INFO - Dependencies all met for dep_context=non-requeueable deps ti=<TaskInstance: gcs_to_bigquery_dag.fetch_transform_data manual__2025-02-01T01:58:21.250902+00:00 [queued]>
[2025-02-01T01:58:22.830+0000] {taskinstance.py:1103} INFO - Dependencies all met for dep_context=requeueable deps ti=<TaskInstance: gcs_to_bigquery_dag.fetch_transform_data manual__2025-02-01T01:58:21.250902+00:00 [queued]>
[2025-02-01T01:58:22.830+0000] {taskinstance.py:1308} INFO - Starting attempt 1 of 2
[2025-02-01T01:58:22.837+0000] {taskinstance.py:1327} INFO - Executing <Task(PythonOperator): fetch_transform_data> on 2025-02-01 01:58:21.250902+00:00
[2025-02-01T01:58:22.841+0000] {standard_task_runner.py:57} INFO - Started process 1176 to run task
[2025-02-01T01:58:22.843+0000] {standard_task_runner.py:84} INFO - Running: ['***', 'tasks', 'run', 'gcs_to_bigquery_dag', 'fetch_transform_data', 'manual__2025-02-01T01:58:21.250902+00:00', '--job-id', '108', '--raw', '--subdir', 'DAGS_FOLDER/json_to_bigquery.py', '--cfg-path', '/tmp/tmpea1kyb28']
[2025-02-01T01:58:22.845+0000] {standard_task_runner.py:85} INFO - Job 108: Subtask fetch_transform_data
[2025-02-01T01:58:22.877+0000] {task_command.py:410} INFO - Running <TaskInstance: gcs_to_bigquery_dag.fetch_transform_data manual__2025-02-01T01:58:21.250902+00:00 [running]> on host 3f33197bb456
[2025-02-01T01:58:22.920+0000] {taskinstance.py:1547} INFO - Exporting env vars: AIRFLOW_CTX_DAG_OWNER='***' AIRFLOW_CTX_DAG_ID='gcs_to_bigquery_dag' AIRFLOW_CTX_TASK_ID='fetch_transform_data' AIRFLOW_CTX_EXECUTION_DATE='2025-02-01T01:58:21.250902+00:00' AIRFLOW_CTX_TRY_NUMBER='1' AIRFLOW_CTX_DAG_RUN_ID='manual__2025-02-01T01:58:21.250902+00:00'
[2025-02-01T01:58:22.926+0000] {base.py:73} INFO - Using connection ID 'google_cloud_default' for task execution.
[2025-02-01T01:58:28.415+0000] {taskinstance.py:1824} ERROR - Task failed with exception
Traceback (most recent call last):
  File "/home/airflow/.local/lib/python3.7/site-packages/airflow/operators/python.py", line 181, in execute
    return_value = self.execute_callable()
  File "/home/airflow/.local/lib/python3.7/site-packages/airflow/operators/python.py", line 198, in execute_callable
    return self.python_callable(*self.op_args, **self.op_kwargs)
  File "/opt/airflow/dags/json_to_bigquery.py", line 35, in fetch_transform_data
    date = data["date"]
TypeError: list indices must be integers or slices, not str
[2025-02-01T01:58:28.427+0000] {taskinstance.py:1350} INFO - Marking task as UP_FOR_RETRY. dag_id=gcs_to_bigquery_dag, task_id=fetch_transform_data, execution_date=20250201T015821, start_date=20250201T015822, end_date=20250201T015828
[2025-02-01T01:58:28.439+0000] {standard_task_runner.py:109} ERROR - Failed to execute job 108 for task fetch_transform_data (list indices must be integers or slices, not str; 1176)
[2025-02-01T01:58:28.485+0000] {local_task_job_runner.py:225} INFO - Task exited with return code 1
[2025-02-01T01:58:28.511+0000] {taskinstance.py:2653} INFO - 0 downstream tasks scheduled from follow-on schedule check
