[2025-01-31T07:20:38.238+0000] {taskinstance.py:1103} INFO - Dependencies all met for dep_context=non-requeueable deps ti=<TaskInstance: naver_flight_pipeline.upload_to_bigquery manual__2025-01-31T07:20:11.397997+00:00 [queued]>
[2025-01-31T07:20:38.243+0000] {taskinstance.py:1103} INFO - Dependencies all met for dep_context=requeueable deps ti=<TaskInstance: naver_flight_pipeline.upload_to_bigquery manual__2025-01-31T07:20:11.397997+00:00 [queued]>
[2025-01-31T07:20:38.243+0000] {taskinstance.py:1308} INFO - Starting attempt 1 of 2
[2025-01-31T07:20:38.251+0000] {taskinstance.py:1327} INFO - Executing <Task(PythonOperator): upload_to_bigquery> on 2025-01-31 07:20:11.397997+00:00
[2025-01-31T07:20:38.255+0000] {standard_task_runner.py:57} INFO - Started process 677 to run task
[2025-01-31T07:20:38.258+0000] {standard_task_runner.py:84} INFO - Running: ['***', 'tasks', 'run', 'naver_flight_pipeline', 'upload_to_bigquery', 'manual__2025-01-31T07:20:11.397997+00:00', '--job-id', '27', '--raw', '--subdir', 'DAGS_FOLDER/naver_flight_dag.py', '--cfg-path', '/tmp/tmpzbkd915o']
[2025-01-31T07:20:38.260+0000] {standard_task_runner.py:85} INFO - Job 27: Subtask upload_to_bigquery
[2025-01-31T07:20:38.302+0000] {task_command.py:410} INFO - Running <TaskInstance: naver_flight_pipeline.upload_to_bigquery manual__2025-01-31T07:20:11.397997+00:00 [running]> on host 3f33197bb456
[2025-01-31T07:20:38.347+0000] {taskinstance.py:1547} INFO - Exporting env vars: AIRFLOW_CTX_DAG_OWNER='***' AIRFLOW_CTX_DAG_ID='naver_flight_pipeline' AIRFLOW_CTX_TASK_ID='upload_to_bigquery' AIRFLOW_CTX_EXECUTION_DATE='2025-01-31T07:20:11.397997+00:00' AIRFLOW_CTX_TRY_NUMBER='1' AIRFLOW_CTX_DAG_RUN_ID='manual__2025-01-31T07:20:11.397997+00:00'
[2025-01-31T07:20:38.354+0000] {taskinstance.py:1824} ERROR - Task failed with exception
Traceback (most recent call last):
  File "/home/airflow/.local/lib/python3.7/site-packages/airflow/operators/python.py", line 181, in execute
    return_value = self.execute_callable()
  File "/home/airflow/.local/lib/python3.7/site-packages/airflow/operators/python.py", line 198, in execute_callable
    return self.python_callable(*self.op_args, **self.op_kwargs)
  File "/opt/airflow/dags/naver_flight_dag.py", line 90, in upload_to_bigquery
    raise ValueError("No records found to upload.")
ValueError: No records found to upload.
[2025-01-31T07:20:38.359+0000] {taskinstance.py:1350} INFO - Marking task as UP_FOR_RETRY. dag_id=naver_flight_pipeline, task_id=upload_to_bigquery, execution_date=20250131T072011, start_date=20250131T072038, end_date=20250131T072038
[2025-01-31T07:20:38.365+0000] {standard_task_runner.py:109} ERROR - Failed to execute job 27 for task upload_to_bigquery (No records found to upload.; 677)
[2025-01-31T07:20:38.399+0000] {local_task_job_runner.py:225} INFO - Task exited with return code 1
[2025-01-31T07:20:38.411+0000] {taskinstance.py:2653} INFO - 0 downstream tasks scheduled from follow-on schedule check
