[2025-01-31T09:24:30.890+0000] {taskinstance.py:1103} INFO - Dependencies all met for dep_context=non-requeueable deps ti=<TaskInstance: naver_flight_pipeline.process_and_upload manual__2025-01-31T09:18:13.085279+00:00 [queued]>
[2025-01-31T09:24:30.895+0000] {taskinstance.py:1103} INFO - Dependencies all met for dep_context=requeueable deps ti=<TaskInstance: naver_flight_pipeline.process_and_upload manual__2025-01-31T09:18:13.085279+00:00 [queued]>
[2025-01-31T09:24:30.895+0000] {taskinstance.py:1308} INFO - Starting attempt 2 of 2
[2025-01-31T09:24:30.902+0000] {taskinstance.py:1327} INFO - Executing <Task(PythonOperator): process_and_upload> on 2025-01-31 09:18:13.085279+00:00
[2025-01-31T09:24:30.905+0000] {standard_task_runner.py:57} INFO - Started process 2464 to run task
[2025-01-31T09:24:30.908+0000] {standard_task_runner.py:84} INFO - Running: ['***', 'tasks', 'run', 'naver_flight_pipeline', 'process_and_upload', 'manual__2025-01-31T09:18:13.085279+00:00', '--job-id', '40', '--raw', '--subdir', 'DAGS_FOLDER/naver_flight_dag.py', '--cfg-path', '/tmp/tmp0hckazyf']
[2025-01-31T09:24:30.909+0000] {standard_task_runner.py:85} INFO - Job 40: Subtask process_and_upload
[2025-01-31T09:24:30.942+0000] {task_command.py:410} INFO - Running <TaskInstance: naver_flight_pipeline.process_and_upload manual__2025-01-31T09:18:13.085279+00:00 [running]> on host 3f33197bb456
[2025-01-31T09:24:31.008+0000] {taskinstance.py:1547} INFO - Exporting env vars: AIRFLOW_CTX_DAG_OWNER='***' AIRFLOW_CTX_DAG_ID='naver_flight_pipeline' AIRFLOW_CTX_TASK_ID='process_and_upload' AIRFLOW_CTX_EXECUTION_DATE='2025-01-31T09:18:13.085279+00:00' AIRFLOW_CTX_TRY_NUMBER='2' AIRFLOW_CTX_DAG_RUN_ID='manual__2025-01-31T09:18:13.085279+00:00'
[2025-01-31T09:24:34.018+0000] {_metadata.py:146} WARNING - Compute Engine Metadata server unavailable on attempt 1 of 3. Reason: timed out
[2025-01-31T09:24:34.024+0000] {_metadata.py:146} WARNING - Compute Engine Metadata server unavailable on attempt 2 of 3. Reason: [Errno 111] Connection refused
[2025-01-31T09:24:34.026+0000] {_metadata.py:146} WARNING - Compute Engine Metadata server unavailable on attempt 3 of 3. Reason: [Errno 111] Connection refused
[2025-01-31T09:24:34.026+0000] {_default.py:341} WARNING - Authentication failed using Compute Engine authentication due to unavailable metadata server.
[2025-01-31T09:24:34.027+0000] {taskinstance.py:1824} ERROR - Task failed with exception
Traceback (most recent call last):
  File "/home/airflow/.local/lib/python3.7/site-packages/airflow/operators/python.py", line 181, in execute
    return_value = self.execute_callable()
  File "/home/airflow/.local/lib/python3.7/site-packages/airflow/operators/python.py", line 198, in execute_callable
    return self.python_callable(*self.op_args, **self.op_kwargs)
  File "/opt/airflow/dags/naver_flight_dag.py", line 75, in process_and_upload
    parsed_data = process_json(gcs_file_path)
  File "/opt/airflow/dags/phaser/pharshing.py", line 24, in process_json
    client = storage.Client()
  File "/home/airflow/.local/lib/python3.7/site-packages/google/cloud/storage/client.py", line 177, in __init__
    _http=_http,
  File "/home/airflow/.local/lib/python3.7/site-packages/google/cloud/client/__init__.py", line 320, in __init__
    _ClientProjectMixin.__init__(self, project=project, credentials=credentials)
  File "/home/airflow/.local/lib/python3.7/site-packages/google/cloud/client/__init__.py", line 268, in __init__
    project = self._determine_default(project)
  File "/home/airflow/.local/lib/python3.7/site-packages/google/cloud/client/__init__.py", line 287, in _determine_default
    return _determine_default_project(project)
  File "/home/airflow/.local/lib/python3.7/site-packages/google/cloud/_helpers/__init__.py", line 152, in _determine_default_project
    _, project = google.auth.default()
  File "/home/airflow/.local/lib/python3.7/site-packages/google/auth/_default.py", line 692, in default
    raise exceptions.DefaultCredentialsError(_CLOUD_SDK_MISSING_CREDENTIALS)
google.auth.exceptions.DefaultCredentialsError: Your default credentials were not found. To set up Application Default Credentials, see https://cloud.google.com/docs/authentication/external/set-up-adc for more information.
[2025-01-31T09:24:34.049+0000] {taskinstance.py:1350} INFO - Marking task as FAILED. dag_id=naver_flight_pipeline, task_id=process_and_upload, execution_date=20250131T091813, start_date=20250131T092430, end_date=20250131T092434
[2025-01-31T09:24:34.064+0000] {standard_task_runner.py:109} ERROR - Failed to execute job 40 for task process_and_upload (Your default credentials were not found. To set up Application Default Credentials, see https://cloud.google.com/docs/authentication/external/set-up-adc for more information.; 2464)
[2025-01-31T09:24:34.094+0000] {local_task_job_runner.py:225} INFO - Task exited with return code 1
[2025-01-31T09:24:34.122+0000] {taskinstance.py:2653} INFO - 0 downstream tasks scheduled from follow-on schedule check
