[2025-02-01T00:50:17.317+0000] {taskinstance.py:1103} INFO - Dependencies all met for dep_context=non-requeueable deps ti=<TaskInstance: test_gcs_to_bigquery.load_ndjson_to_bigquery manual__2025-02-01T00:50:10.567653+00:00 [queued]>
[2025-02-01T00:50:17.322+0000] {taskinstance.py:1103} INFO - Dependencies all met for dep_context=requeueable deps ti=<TaskInstance: test_gcs_to_bigquery.load_ndjson_to_bigquery manual__2025-02-01T00:50:10.567653+00:00 [queued]>
[2025-02-01T00:50:17.323+0000] {taskinstance.py:1308} INFO - Starting attempt 1 of 2
[2025-02-01T00:50:17.331+0000] {taskinstance.py:1327} INFO - Executing <Task(PythonOperator): load_ndjson_to_bigquery> on 2025-02-01 00:50:10.567653+00:00
[2025-02-01T00:50:17.337+0000] {standard_task_runner.py:57} INFO - Started process 1784 to run task
[2025-02-01T00:50:17.343+0000] {standard_task_runner.py:84} INFO - Running: ['***', 'tasks', 'run', 'test_gcs_to_bigquery', 'load_ndjson_to_bigquery', 'manual__2025-02-01T00:50:10.567653+00:00', '--job-id', '75', '--raw', '--subdir', 'DAGS_FOLDER/bigquery_test_dag.py', '--cfg-path', '/tmp/tmp_6gpxcq4']
[2025-02-01T00:50:17.349+0000] {standard_task_runner.py:85} INFO - Job 75: Subtask load_ndjson_to_bigquery
[2025-02-01T00:50:17.378+0000] {task_command.py:410} INFO - Running <TaskInstance: test_gcs_to_bigquery.load_ndjson_to_bigquery manual__2025-02-01T00:50:10.567653+00:00 [running]> on host 3f33197bb456
[2025-02-01T00:50:17.426+0000] {taskinstance.py:1547} INFO - Exporting env vars: AIRFLOW_CTX_DAG_OWNER='***' AIRFLOW_CTX_DAG_ID='test_gcs_to_bigquery' AIRFLOW_CTX_TASK_ID='load_ndjson_to_bigquery' AIRFLOW_CTX_EXECUTION_DATE='2025-02-01T00:50:10.567653+00:00' AIRFLOW_CTX_TRY_NUMBER='1' AIRFLOW_CTX_DAG_RUN_ID='manual__2025-02-01T00:50:10.567653+00:00'
[2025-02-01T00:50:17.432+0000] {base.py:73} INFO - Using connection ID 'google_cloud_default' for task execution.
[2025-02-01T00:50:18.027+0000] {taskinstance.py:1824} ERROR - Task failed with exception
Traceback (most recent call last):
  File "/home/airflow/.local/lib/python3.7/site-packages/airflow/operators/python.py", line 181, in execute
    return_value = self.execute_callable()
  File "/home/airflow/.local/lib/python3.7/site-packages/airflow/operators/python.py", line 198, in execute_callable
    return self.python_callable(*self.op_args, **self.op_kwargs)
  File "/opt/airflow/dags/bigquery_test_dag.py", line 87, in load_ndjson_to_bigquery
    job_config = bigquery.LoadJobConfig(
NameError: name 'bigquery' is not defined
[2025-02-01T00:50:18.054+0000] {taskinstance.py:1350} INFO - Marking task as UP_FOR_RETRY. dag_id=test_gcs_to_bigquery, task_id=load_ndjson_to_bigquery, execution_date=20250201T005010, start_date=20250201T005017, end_date=20250201T005018
[2025-02-01T00:50:18.067+0000] {standard_task_runner.py:109} ERROR - Failed to execute job 75 for task load_ndjson_to_bigquery (name 'bigquery' is not defined; 1784)
[2025-02-01T00:50:18.097+0000] {local_task_job_runner.py:225} INFO - Task exited with return code 1
[2025-02-01T00:50:18.116+0000] {taskinstance.py:2653} INFO - 0 downstream tasks scheduled from follow-on schedule check
