[2025-01-30T05:51:40.271+0000] {taskinstance.py:1103} INFO - Dependencies all met for dep_context=non-requeueable deps ti=<TaskInstance: gcs_connection_check.check_gcs manual__2025-01-30T05:51:37.446481+00:00 [queued]>
[2025-01-30T05:51:40.276+0000] {taskinstance.py:1103} INFO - Dependencies all met for dep_context=requeueable deps ti=<TaskInstance: gcs_connection_check.check_gcs manual__2025-01-30T05:51:37.446481+00:00 [queued]>
[2025-01-30T05:51:40.276+0000] {taskinstance.py:1308} INFO - Starting attempt 1 of 2
[2025-01-30T05:51:40.284+0000] {taskinstance.py:1327} INFO - Executing <Task(PythonOperator): check_gcs> on 2025-01-30 05:51:37.446481+00:00
[2025-01-30T05:51:40.291+0000] {standard_task_runner.py:57} INFO - Started process 173 to run task
[2025-01-30T05:51:40.293+0000] {standard_task_runner.py:84} INFO - Running: ['***', 'tasks', 'run', 'gcs_connection_check', 'check_gcs', 'manual__2025-01-30T05:51:37.446481+00:00', '--job-id', '3', '--raw', '--subdir', 'DAGS_FOLDER/gcs_check_dag.py', '--cfg-path', '/tmp/tmpm8o7q6xj']
[2025-01-30T05:51:40.296+0000] {standard_task_runner.py:85} INFO - Job 3: Subtask check_gcs
[2025-01-30T05:51:40.328+0000] {task_command.py:410} INFO - Running <TaskInstance: gcs_connection_check.check_gcs manual__2025-01-30T05:51:37.446481+00:00 [running]> on host 3f33197bb456
[2025-01-30T05:51:40.378+0000] {taskinstance.py:1547} INFO - Exporting env vars: AIRFLOW_CTX_DAG_OWNER='***' AIRFLOW_CTX_DAG_ID='gcs_connection_check' AIRFLOW_CTX_TASK_ID='check_gcs' AIRFLOW_CTX_EXECUTION_DATE='2025-01-30T05:51:37.446481+00:00' AIRFLOW_CTX_TRY_NUMBER='1' AIRFLOW_CTX_DAG_RUN_ID='manual__2025-01-30T05:51:37.446481+00:00'
[2025-01-30T05:51:40.384+0000] {base.py:73} INFO - Using connection ID 'google_cloud_default' for task execution.
[2025-01-30T05:51:40.384+0000] {credentials_provider.py:323} INFO - Getting connection using `google.auth.default()` since no key file is defined for hook.
[2025-01-30T05:51:43.395+0000] {_metadata.py:146} WARNING - Compute Engine Metadata server unavailable on attempt 1 of 3. Reason: timed out
[2025-01-30T05:51:43.402+0000] {_metadata.py:146} WARNING - Compute Engine Metadata server unavailable on attempt 2 of 3. Reason: [Errno 111] Connection refused
[2025-01-30T05:51:43.403+0000] {_metadata.py:146} WARNING - Compute Engine Metadata server unavailable on attempt 3 of 3. Reason: [Errno 111] Connection refused
[2025-01-30T05:51:43.404+0000] {_default.py:341} WARNING - Authentication failed using Compute Engine authentication due to unavailable metadata server.
[2025-01-30T05:51:43.404+0000] {credentials_provider.py:323} INFO - Getting connection using `google.auth.default()` since no key file is defined for hook.
[2025-01-30T05:51:43.406+0000] {_metadata.py:146} WARNING - Compute Engine Metadata server unavailable on attempt 1 of 3. Reason: [Errno 111] Connection refused
[2025-01-30T05:51:43.407+0000] {_metadata.py:146} WARNING - Compute Engine Metadata server unavailable on attempt 2 of 3. Reason: [Errno 111] Connection refused
[2025-01-30T05:51:43.408+0000] {_metadata.py:146} WARNING - Compute Engine Metadata server unavailable on attempt 3 of 3. Reason: [Errno 111] Connection refused
[2025-01-30T05:51:43.408+0000] {_default.py:341} WARNING - Authentication failed using Compute Engine authentication due to unavailable metadata server.
[2025-01-30T05:51:43.410+0000] {taskinstance.py:1824} ERROR - Task failed with exception
Traceback (most recent call last):
  File "/opt/airflow/dags/gcs_check_dag.py", line 19, in check_gcs_connection
    hook.upload(bucket_name=GCS_BUCKET_NAME, object_name=GCS_OBJECT_NAME, data=json.dumps({"result": "success"}))
  File "/home/airflow/.local/lib/python3.7/site-packages/airflow/providers/google/cloud/hooks/gcs.py", line 508, in upload
    client = self.get_conn()
  File "/home/airflow/.local/lib/python3.7/site-packages/airflow/providers/google/cloud/hooks/gcs.py", line 172, in get_conn
    credentials=self.get_credentials(), client_info=CLIENT_INFO, project=self.project_id
  File "/home/airflow/.local/lib/python3.7/site-packages/airflow/providers/google/common/hooks/base_google.py", line 281, in get_credentials
    credentials, _ = self.get_credentials_and_project_id()
  File "/home/airflow/.local/lib/python3.7/site-packages/airflow/providers/google/common/hooks/base_google.py", line 267, in get_credentials_and_project_id
    delegates=delegates,
  File "/home/airflow/.local/lib/python3.7/site-packages/airflow/providers/google/cloud/utils/credentials_provider.py", line 332, in get_credentials_and_project_id
    return _CredentialProvider(*args, **kwargs).get_credentials_and_project()
  File "/home/airflow/.local/lib/python3.7/site-packages/airflow/providers/google/cloud/utils/credentials_provider.py", line 237, in get_credentials_and_project
    credentials, project_id = self._get_credentials_using_adc()
  File "/home/airflow/.local/lib/python3.7/site-packages/airflow/providers/google/cloud/utils/credentials_provider.py", line 318, in _get_credentials_using_adc
    credentials, project_id = google.auth.default(scopes=self.scopes)
  File "/home/airflow/.local/lib/python3.7/site-packages/google/auth/_default.py", line 692, in default
    raise exceptions.DefaultCredentialsError(_CLOUD_SDK_MISSING_CREDENTIALS)
google.auth.exceptions.DefaultCredentialsError: Your default credentials were not found. To set up Application Default Credentials, see https://cloud.google.com/docs/authentication/external/set-up-adc for more information.

During handling of the above exception, another exception occurred:

Traceback (most recent call last):
  File "/home/airflow/.local/lib/python3.7/site-packages/airflow/operators/python.py", line 181, in execute
    return_value = self.execute_callable()
  File "/home/airflow/.local/lib/python3.7/site-packages/airflow/operators/python.py", line 198, in execute_callable
    return self.python_callable(*self.op_args, **self.op_kwargs)
  File "/opt/airflow/dags/gcs_check_dag.py", line 21, in check_gcs_connection
    hook.upload(bucket_name=GCS_BUCKET_NAME, object_name=GCS_OBJECT_NAME, data=json.dumps({"result": str(e)}))
  File "/home/airflow/.local/lib/python3.7/site-packages/airflow/providers/google/cloud/hooks/gcs.py", line 508, in upload
    client = self.get_conn()
  File "/home/airflow/.local/lib/python3.7/site-packages/airflow/providers/google/cloud/hooks/gcs.py", line 172, in get_conn
    credentials=self.get_credentials(), client_info=CLIENT_INFO, project=self.project_id
  File "/home/airflow/.local/lib/python3.7/site-packages/airflow/providers/google/common/hooks/base_google.py", line 281, in get_credentials
    credentials, _ = self.get_credentials_and_project_id()
  File "/home/airflow/.local/lib/python3.7/site-packages/airflow/providers/google/common/hooks/base_google.py", line 267, in get_credentials_and_project_id
    delegates=delegates,
  File "/home/airflow/.local/lib/python3.7/site-packages/airflow/providers/google/cloud/utils/credentials_provider.py", line 332, in get_credentials_and_project_id
    return _CredentialProvider(*args, **kwargs).get_credentials_and_project()
  File "/home/airflow/.local/lib/python3.7/site-packages/airflow/providers/google/cloud/utils/credentials_provider.py", line 237, in get_credentials_and_project
    credentials, project_id = self._get_credentials_using_adc()
  File "/home/airflow/.local/lib/python3.7/site-packages/airflow/providers/google/cloud/utils/credentials_provider.py", line 318, in _get_credentials_using_adc
    credentials, project_id = google.auth.default(scopes=self.scopes)
  File "/home/airflow/.local/lib/python3.7/site-packages/google/auth/_default.py", line 692, in default
    raise exceptions.DefaultCredentialsError(_CLOUD_SDK_MISSING_CREDENTIALS)
google.auth.exceptions.DefaultCredentialsError: Your default credentials were not found. To set up Application Default Credentials, see https://cloud.google.com/docs/authentication/external/set-up-adc for more information.
[2025-01-30T05:51:43.441+0000] {taskinstance.py:1350} INFO - Marking task as UP_FOR_RETRY. dag_id=gcs_connection_check, task_id=check_gcs, execution_date=20250130T055137, start_date=20250130T055140, end_date=20250130T055143
[2025-01-30T05:51:43.458+0000] {standard_task_runner.py:109} ERROR - Failed to execute job 3 for task check_gcs (Your default credentials were not found. To set up Application Default Credentials, see https://cloud.google.com/docs/authentication/external/set-up-adc for more information.; 173)
[2025-01-30T05:51:43.469+0000] {local_task_job_runner.py:225} INFO - Task exited with return code 1
[2025-01-30T05:51:43.505+0000] {taskinstance.py:2653} INFO - 0 downstream tasks scheduled from follow-on schedule check
