[2025-02-01T01:39:51.122+0000] {taskinstance.py:1103} INFO - Dependencies all met for dep_context=non-requeueable deps ti=<TaskInstance: naver_flight_bigquery_pipeline.process_flight_data manual__2025-02-01T01:39:49.402109+00:00 [queued]>
[2025-02-01T01:39:51.126+0000] {taskinstance.py:1103} INFO - Dependencies all met for dep_context=requeueable deps ti=<TaskInstance: naver_flight_bigquery_pipeline.process_flight_data manual__2025-02-01T01:39:49.402109+00:00 [queued]>
[2025-02-01T01:39:51.126+0000] {taskinstance.py:1308} INFO - Starting attempt 1 of 2
[2025-02-01T01:39:51.134+0000] {taskinstance.py:1327} INFO - Executing <Task(PythonOperator): process_flight_data> on 2025-02-01 01:39:49.402109+00:00
[2025-02-01T01:39:51.139+0000] {standard_task_runner.py:57} INFO - Started process 568 to run task
[2025-02-01T01:39:51.141+0000] {standard_task_runner.py:84} INFO - Running: ['***', 'tasks', 'run', 'naver_flight_bigquery_pipeline', 'process_flight_data', 'manual__2025-02-01T01:39:49.402109+00:00', '--job-id', '105', '--raw', '--subdir', 'DAGS_FOLDER/json_to_bigquery.py', '--cfg-path', '/tmp/tmpqo7bkglu']
[2025-02-01T01:39:51.143+0000] {standard_task_runner.py:85} INFO - Job 105: Subtask process_flight_data
[2025-02-01T01:39:51.191+0000] {task_command.py:410} INFO - Running <TaskInstance: naver_flight_bigquery_pipeline.process_flight_data manual__2025-02-01T01:39:49.402109+00:00 [running]> on host 3f33197bb456
[2025-02-01T01:39:51.241+0000] {taskinstance.py:1547} INFO - Exporting env vars: AIRFLOW_CTX_DAG_OWNER='***' AIRFLOW_CTX_DAG_ID='naver_flight_bigquery_pipeline' AIRFLOW_CTX_TASK_ID='process_flight_data' AIRFLOW_CTX_EXECUTION_DATE='2025-02-01T01:39:49.402109+00:00' AIRFLOW_CTX_TRY_NUMBER='1' AIRFLOW_CTX_DAG_RUN_ID='manual__2025-02-01T01:39:49.402109+00:00'
[2025-02-01T01:39:51.247+0000] {base.py:73} INFO - Using connection ID 'google_cloud_default' for task execution.
[2025-02-01T01:39:57.615+0000] {base.py:73} INFO - Using connection ID 'google_cloud_default' for task execution.
[2025-02-01T01:39:57.624+0000] {taskinstance.py:1824} ERROR - Task failed with exception
Traceback (most recent call last):
  File "/home/airflow/.local/lib/python3.7/site-packages/airflow/operators/python.py", line 181, in execute
    return_value = self.execute_callable()
  File "/home/airflow/.local/lib/python3.7/site-packages/airflow/operators/python.py", line 198, in execute_callable
    return self.python_callable(*self.op_args, **self.op_kwargs)
  File "/opt/airflow/dags/json_to_bigquery.py", line 91, in upload_to_bigquery
    hook_bq.insert_rows(table=table_ref, rows=df.to_dict(orient='records'))
  File "/home/airflow/.local/lib/python3.7/site-packages/airflow/providers/google/cloud/hooks/bigquery.py", line 236, in insert_rows
    raise NotImplementedError()
NotImplementedError
[2025-02-01T01:39:57.635+0000] {taskinstance.py:1350} INFO - Marking task as UP_FOR_RETRY. dag_id=naver_flight_bigquery_pipeline, task_id=process_flight_data, execution_date=20250201T013949, start_date=20250201T013951, end_date=20250201T013957
[2025-02-01T01:39:57.645+0000] {standard_task_runner.py:109} ERROR - Failed to execute job 105 for task process_flight_data (; 568)
[2025-02-01T01:39:57.673+0000] {local_task_job_runner.py:225} INFO - Task exited with return code 1
[2025-02-01T01:39:57.691+0000] {taskinstance.py:2653} INFO - 0 downstream tasks scheduled from follow-on schedule check
