[2025-02-01T00:42:14.651+0000] {taskinstance.py:1103} INFO - Dependencies all met for dep_context=non-requeueable deps ti=<TaskInstance: test_gcs_to_bigquery.load_gcs_to_bigquery manual__2025-02-01T00:42:12.762723+00:00 [queued]>
[2025-02-01T00:42:14.655+0000] {taskinstance.py:1103} INFO - Dependencies all met for dep_context=requeueable deps ti=<TaskInstance: test_gcs_to_bigquery.load_gcs_to_bigquery manual__2025-02-01T00:42:12.762723+00:00 [queued]>
[2025-02-01T00:42:14.655+0000] {taskinstance.py:1308} INFO - Starting attempt 1 of 2
[2025-02-01T00:42:14.663+0000] {taskinstance.py:1327} INFO - Executing <Task(PythonOperator): load_gcs_to_bigquery> on 2025-02-01 00:42:12.762723+00:00
[2025-02-01T00:42:14.666+0000] {standard_task_runner.py:57} INFO - Started process 1486 to run task
[2025-02-01T00:42:14.669+0000] {standard_task_runner.py:84} INFO - Running: ['***', 'tasks', 'run', 'test_gcs_to_bigquery', 'load_gcs_to_bigquery', 'manual__2025-02-01T00:42:12.762723+00:00', '--job-id', '72', '--raw', '--subdir', 'DAGS_FOLDER/bigquery_test_dag.py', '--cfg-path', '/tmp/tmpyouf558a']
[2025-02-01T00:42:14.672+0000] {standard_task_runner.py:85} INFO - Job 72: Subtask load_gcs_to_bigquery
[2025-02-01T00:42:14.702+0000] {task_command.py:410} INFO - Running <TaskInstance: test_gcs_to_bigquery.load_gcs_to_bigquery manual__2025-02-01T00:42:12.762723+00:00 [running]> on host 3f33197bb456
[2025-02-01T00:42:14.753+0000] {taskinstance.py:1547} INFO - Exporting env vars: AIRFLOW_CTX_DAG_OWNER='***' AIRFLOW_CTX_DAG_ID='test_gcs_to_bigquery' AIRFLOW_CTX_TASK_ID='load_gcs_to_bigquery' AIRFLOW_CTX_EXECUTION_DATE='2025-02-01T00:42:12.762723+00:00' AIRFLOW_CTX_TRY_NUMBER='1' AIRFLOW_CTX_DAG_RUN_ID='manual__2025-02-01T00:42:12.762723+00:00'
[2025-02-01T00:42:14.760+0000] {base.py:73} INFO - Using connection ID 'google_cloud_default' for task execution.
[2025-02-01T00:42:17.471+0000] {logging_mixin.py:150} INFO - [ERROR] BigQuery 로드 실패: 400 Error while reading data, error message: JSON table encountered too many errors, giving up. Rows: 1; errors: 1. Please look into the errors[] collection for more details. File: gs://ticket_checker_bucket/naver_flight_data/flight_results.json
[2025-02-01T00:42:17.473+0000] {python.py:183} INFO - Done. Returned value was: None
[2025-02-01T00:42:17.513+0000] {taskinstance.py:1350} INFO - Marking task as SUCCESS. dag_id=test_gcs_to_bigquery, task_id=load_gcs_to_bigquery, execution_date=20250201T004212, start_date=20250201T004214, end_date=20250201T004217
[2025-02-01T00:42:17.543+0000] {local_task_job_runner.py:225} INFO - Task exited with return code 0
[2025-02-01T00:42:17.563+0000] {taskinstance.py:2653} INFO - 0 downstream tasks scheduled from follow-on schedule check
