[2025-01-31T07:12:12.965+0000] {taskinstance.py:1103} INFO - Dependencies all met for dep_context=non-requeueable deps ti=<TaskInstance: naver_flight_pipeline.process_json manual__2025-01-31T07:10:41.414256+00:00 [queued]>
[2025-01-31T07:12:12.970+0000] {taskinstance.py:1103} INFO - Dependencies all met for dep_context=requeueable deps ti=<TaskInstance: naver_flight_pipeline.process_json manual__2025-01-31T07:10:41.414256+00:00 [queued]>
[2025-01-31T07:12:12.970+0000] {taskinstance.py:1308} INFO - Starting attempt 1 of 2
[2025-01-31T07:12:12.977+0000] {taskinstance.py:1327} INFO - Executing <Task(PythonOperator): process_json> on 2025-01-31 07:10:41.414256+00:00
[2025-01-31T07:12:12.980+0000] {standard_task_runner.py:57} INFO - Started process 380 to run task
[2025-01-31T07:12:12.982+0000] {standard_task_runner.py:84} INFO - Running: ['***', 'tasks', 'run', 'naver_flight_pipeline', 'process_json', 'manual__2025-01-31T07:10:41.414256+00:00', '--job-id', '15', '--raw', '--subdir', 'DAGS_FOLDER/naver_flight_dag.py', '--cfg-path', '/tmp/tmp2zdi0yyd']
[2025-01-31T07:12:12.984+0000] {standard_task_runner.py:85} INFO - Job 15: Subtask process_json
[2025-01-31T07:12:13.010+0000] {task_command.py:410} INFO - Running <TaskInstance: naver_flight_pipeline.process_json manual__2025-01-31T07:10:41.414256+00:00 [running]> on host 3f33197bb456
[2025-01-31T07:12:13.060+0000] {taskinstance.py:1547} INFO - Exporting env vars: AIRFLOW_CTX_DAG_OWNER='***' AIRFLOW_CTX_DAG_ID='naver_flight_pipeline' AIRFLOW_CTX_TASK_ID='process_json' AIRFLOW_CTX_EXECUTION_DATE='2025-01-31T07:10:41.414256+00:00' AIRFLOW_CTX_TRY_NUMBER='1' AIRFLOW_CTX_DAG_RUN_ID='manual__2025-01-31T07:10:41.414256+00:00'
[2025-01-31T07:12:13.074+0000] {taskinstance.py:1824} ERROR - Task failed with exception
Traceback (most recent call last):
  File "/home/airflow/.local/lib/python3.7/site-packages/airflow/operators/python.py", line 181, in execute
    return_value = self.execute_callable()
  File "/home/airflow/.local/lib/python3.7/site-packages/airflow/operators/python.py", line 198, in execute_callable
    return self.python_callable(*self.op_args, **self.op_kwargs)
  File "/opt/airflow/dags/phaser/pharshing.py", line 41, in process_json
    fare = flight.get("lowest_price_adult")
AttributeError: 'str' object has no attribute 'get'
[2025-01-31T07:12:13.079+0000] {taskinstance.py:1350} INFO - Marking task as UP_FOR_RETRY. dag_id=naver_flight_pipeline, task_id=process_json, execution_date=20250131T071041, start_date=20250131T071212, end_date=20250131T071213
[2025-01-31T07:12:13.087+0000] {standard_task_runner.py:109} ERROR - Failed to execute job 15 for task process_json ('str' object has no attribute 'get'; 380)
[2025-01-31T07:12:13.124+0000] {local_task_job_runner.py:225} INFO - Task exited with return code 1
[2025-01-31T07:12:13.141+0000] {taskinstance.py:2653} INFO - 0 downstream tasks scheduled from follow-on schedule check
