[2025-02-01T02:36:53.808+0000] {taskinstance.py:1103} INFO - Dependencies all met for dep_context=non-requeueable deps ti=<TaskInstance: gcs_to_bigquery_dag.fetch_transform_data manual__2025-02-01T02:36:52.137744+00:00 [queued]>
[2025-02-01T02:36:53.814+0000] {taskinstance.py:1103} INFO - Dependencies all met for dep_context=requeueable deps ti=<TaskInstance: gcs_to_bigquery_dag.fetch_transform_data manual__2025-02-01T02:36:52.137744+00:00 [queued]>
[2025-02-01T02:36:53.815+0000] {taskinstance.py:1308} INFO - Starting attempt 1 of 2
[2025-02-01T02:36:53.824+0000] {taskinstance.py:1327} INFO - Executing <Task(PythonOperator): fetch_transform_data> on 2025-02-01 02:36:52.137744+00:00
[2025-02-01T02:36:53.828+0000] {standard_task_runner.py:57} INFO - Started process 2695 to run task
[2025-02-01T02:36:53.831+0000] {standard_task_runner.py:84} INFO - Running: ['***', 'tasks', 'run', 'gcs_to_bigquery_dag', 'fetch_transform_data', 'manual__2025-02-01T02:36:52.137744+00:00', '--job-id', '137', '--raw', '--subdir', 'DAGS_FOLDER/json_to_bigquery.py', '--cfg-path', '/tmp/tmpba99z4xf']
[2025-02-01T02:36:53.834+0000] {standard_task_runner.py:85} INFO - Job 137: Subtask fetch_transform_data
[2025-02-01T02:36:53.865+0000] {task_command.py:410} INFO - Running <TaskInstance: gcs_to_bigquery_dag.fetch_transform_data manual__2025-02-01T02:36:52.137744+00:00 [running]> on host 3f33197bb456
[2025-02-01T02:36:53.922+0000] {taskinstance.py:1547} INFO - Exporting env vars: AIRFLOW_CTX_DAG_OWNER='***' AIRFLOW_CTX_DAG_ID='gcs_to_bigquery_dag' AIRFLOW_CTX_TASK_ID='fetch_transform_data' AIRFLOW_CTX_EXECUTION_DATE='2025-02-01T02:36:52.137744+00:00' AIRFLOW_CTX_TRY_NUMBER='1' AIRFLOW_CTX_DAG_RUN_ID='manual__2025-02-01T02:36:52.137744+00:00'
[2025-02-01T02:36:53.928+0000] {base.py:73} INFO - Using connection ID 'google_cloud_default' for task execution.
[2025-02-01T02:37:13.084+0000] {taskinstance.py:1824} ERROR - Task failed with exception
Traceback (most recent call last):
  File "/home/airflow/.local/lib/python3.7/site-packages/airflow/operators/python.py", line 181, in execute
    return_value = self.execute_callable()
  File "/home/airflow/.local/lib/python3.7/site-packages/airflow/operators/python.py", line 198, in execute_callable
    return self.python_callable(*self.op_args, **self.op_kwargs)
  File "/opt/airflow/dags/json_to_bigquery.py", line 62, in fetch_transform_data
    for flight_id, flight_details in schedules.items():
AttributeError: 'list' object has no attribute 'items'
[2025-02-01T02:37:13.101+0000] {taskinstance.py:1350} INFO - Marking task as UP_FOR_RETRY. dag_id=gcs_to_bigquery_dag, task_id=fetch_transform_data, execution_date=20250201T023652, start_date=20250201T023653, end_date=20250201T023713
[2025-02-01T02:37:13.118+0000] {standard_task_runner.py:109} ERROR - Failed to execute job 137 for task fetch_transform_data ('list' object has no attribute 'items'; 2695)
[2025-02-01T02:37:13.165+0000] {local_task_job_runner.py:225} INFO - Task exited with return code 1
[2025-02-01T02:37:13.192+0000] {taskinstance.py:2653} INFO - 0 downstream tasks scheduled from follow-on schedule check
