[2025-02-01T01:30:11.507+0000] {taskinstance.py:1103} INFO - Dependencies all met for dep_context=non-requeueable deps ti=<TaskInstance: naver_flight_bigquery_pipeline.process_flight_data manual__2025-02-01T01:30:09.552178+00:00 [queued]>
[2025-02-01T01:30:11.513+0000] {taskinstance.py:1103} INFO - Dependencies all met for dep_context=requeueable deps ti=<TaskInstance: naver_flight_bigquery_pipeline.process_flight_data manual__2025-02-01T01:30:09.552178+00:00 [queued]>
[2025-02-01T01:30:11.513+0000] {taskinstance.py:1308} INFO - Starting attempt 1 of 2
[2025-02-01T01:30:11.522+0000] {taskinstance.py:1327} INFO - Executing <Task(PythonOperator): process_flight_data> on 2025-02-01 01:30:09.552178+00:00
[2025-02-01T01:30:11.527+0000] {standard_task_runner.py:57} INFO - Started process 212 to run task
[2025-02-01T01:30:11.530+0000] {standard_task_runner.py:84} INFO - Running: ['***', 'tasks', 'run', 'naver_flight_bigquery_pipeline', 'process_flight_data', 'manual__2025-02-01T01:30:09.552178+00:00', '--job-id', '99', '--raw', '--subdir', 'DAGS_FOLDER/json_to_bigquery.py', '--cfg-path', '/tmp/tmpsf57w8u_']
[2025-02-01T01:30:11.533+0000] {standard_task_runner.py:85} INFO - Job 99: Subtask process_flight_data
[2025-02-01T01:30:11.563+0000] {task_command.py:410} INFO - Running <TaskInstance: naver_flight_bigquery_pipeline.process_flight_data manual__2025-02-01T01:30:09.552178+00:00 [running]> on host 3f33197bb456
[2025-02-01T01:30:11.623+0000] {taskinstance.py:1547} INFO - Exporting env vars: AIRFLOW_CTX_DAG_OWNER='***' AIRFLOW_CTX_DAG_ID='naver_flight_bigquery_pipeline' AIRFLOW_CTX_TASK_ID='process_flight_data' AIRFLOW_CTX_EXECUTION_DATE='2025-02-01T01:30:09.552178+00:00' AIRFLOW_CTX_TRY_NUMBER='1' AIRFLOW_CTX_DAG_RUN_ID='manual__2025-02-01T01:30:09.552178+00:00'
[2025-02-01T01:30:11.631+0000] {base.py:73} INFO - Using connection ID 'google_cloud_default' for task execution.
[2025-02-01T01:30:14.944+0000] {taskinstance.py:1824} ERROR - Task failed with exception
Traceback (most recent call last):
  File "/home/airflow/.local/lib/python3.7/site-packages/airflow/operators/python.py", line 181, in execute
    return_value = self.execute_callable()
  File "/home/airflow/.local/lib/python3.7/site-packages/airflow/operators/python.py", line 198, in execute_callable
    return self.python_callable(*self.op_args, **self.op_kwargs)
  File "/opt/airflow/dags/json_to_bigquery.py", line 77, in upload_to_bigquery
    processed_data = extract_flight_data()
  File "/opt/airflow/dags/json_to_bigquery.py", line 28, in extract_flight_data
    fares = flight_data.get("fares", {})
AttributeError: 'list' object has no attribute 'get'
[2025-02-01T01:30:14.966+0000] {taskinstance.py:1350} INFO - Marking task as UP_FOR_RETRY. dag_id=naver_flight_bigquery_pipeline, task_id=process_flight_data, execution_date=20250201T013009, start_date=20250201T013011, end_date=20250201T013014
[2025-02-01T01:30:14.977+0000] {standard_task_runner.py:109} ERROR - Failed to execute job 99 for task process_flight_data ('list' object has no attribute 'get'; 212)
[2025-02-01T01:30:15.034+0000] {local_task_job_runner.py:225} INFO - Task exited with return code 1
[2025-02-01T01:30:15.059+0000] {taskinstance.py:2653} INFO - 0 downstream tasks scheduled from follow-on schedule check
