[2025-02-01T02:27:32.096+0000] {taskinstance.py:1103} INFO - Dependencies all met for dep_context=non-requeueable deps ti=<TaskInstance: gcs_to_bigquery_dag.fetch_transform_data manual__2025-02-01T02:27:30.429974+00:00 [queued]>
[2025-02-01T02:27:32.101+0000] {taskinstance.py:1103} INFO - Dependencies all met for dep_context=requeueable deps ti=<TaskInstance: gcs_to_bigquery_dag.fetch_transform_data manual__2025-02-01T02:27:30.429974+00:00 [queued]>
[2025-02-01T02:27:32.101+0000] {taskinstance.py:1308} INFO - Starting attempt 1 of 2
[2025-02-01T02:27:32.128+0000] {taskinstance.py:1327} INFO - Executing <Task(PythonOperator): fetch_transform_data> on 2025-02-01 02:27:30.429974+00:00
[2025-02-01T02:27:32.134+0000] {standard_task_runner.py:57} INFO - Started process 2376 to run task
[2025-02-01T02:27:32.138+0000] {standard_task_runner.py:84} INFO - Running: ['***', 'tasks', 'run', 'gcs_to_bigquery_dag', 'fetch_transform_data', 'manual__2025-02-01T02:27:30.429974+00:00', '--job-id', '133', '--raw', '--subdir', 'DAGS_FOLDER/json_to_bigquery.py', '--cfg-path', '/tmp/tmpzvmgn4uh']
[2025-02-01T02:27:32.141+0000] {standard_task_runner.py:85} INFO - Job 133: Subtask fetch_transform_data
[2025-02-01T02:27:32.190+0000] {task_command.py:410} INFO - Running <TaskInstance: gcs_to_bigquery_dag.fetch_transform_data manual__2025-02-01T02:27:30.429974+00:00 [running]> on host 3f33197bb456
[2025-02-01T02:27:32.247+0000] {taskinstance.py:1547} INFO - Exporting env vars: AIRFLOW_CTX_DAG_OWNER='***' AIRFLOW_CTX_DAG_ID='gcs_to_bigquery_dag' AIRFLOW_CTX_TASK_ID='fetch_transform_data' AIRFLOW_CTX_EXECUTION_DATE='2025-02-01T02:27:30.429974+00:00' AIRFLOW_CTX_TRY_NUMBER='1' AIRFLOW_CTX_DAG_RUN_ID='manual__2025-02-01T02:27:30.429974+00:00'
[2025-02-01T02:27:32.252+0000] {base.py:73} INFO - Using connection ID 'google_cloud_default' for task execution.
[2025-02-01T02:27:47.476+0000] {taskinstance.py:1824} ERROR - Task failed with exception
Traceback (most recent call last):
  File "/home/airflow/.local/lib/python3.7/site-packages/airflow/operators/python.py", line 181, in execute
    return_value = self.execute_callable()
  File "/home/airflow/.local/lib/python3.7/site-packages/airflow/operators/python.py", line 198, in execute_callable
    return self.python_callable(*self.op_args, **self.op_kwargs)
  File "/opt/airflow/dags/json_to_bigquery.py", line 54, in fetch_transform_data
    for flight_id, flight_details in schedules.items():
AttributeError: 'list' object has no attribute 'items'
[2025-02-01T02:27:47.512+0000] {taskinstance.py:1350} INFO - Marking task as UP_FOR_RETRY. dag_id=gcs_to_bigquery_dag, task_id=fetch_transform_data, execution_date=20250201T022730, start_date=20250201T022732, end_date=20250201T022747
[2025-02-01T02:27:47.526+0000] {standard_task_runner.py:109} ERROR - Failed to execute job 133 for task fetch_transform_data ('list' object has no attribute 'items'; 2376)
[2025-02-01T02:27:47.541+0000] {local_task_job_runner.py:225} INFO - Task exited with return code 1
[2025-02-01T02:27:47.562+0000] {taskinstance.py:2653} INFO - 0 downstream tasks scheduled from follow-on schedule check
